2025-09-03 10:40:01,519 INFO    MainThread:36585 [wandb_setup.py:_flush():81] Current SDK version is 0.21.3
2025-09-03 10:40:01,519 INFO    MainThread:36585 [wandb_setup.py:_flush():81] Configure stats pid to 36585
2025-09-03 10:40:01,519 INFO    MainThread:36585 [wandb_setup.py:_flush():81] Loading settings from /home/sebastian/.config/wandb/settings
2025-09-03 10:40:01,519 INFO    MainThread:36585 [wandb_setup.py:_flush():81] Loading settings from /home/sebastian/Documents/smaller_projects/TOPR-RL/torchrl_sac/outputs/2025-09-03/10-40-00/wandb/settings
2025-09-03 10:40:01,519 INFO    MainThread:36585 [wandb_setup.py:_flush():81] Loading settings from environment variables
2025-09-03 10:40:01,519 INFO    MainThread:36585 [wandb_init.py:setup_run_log_directory():686] Logging user logs to sac_logging/wandb/run-20250903_104001-rj1c970k/logs/debug.log
2025-09-03 10:40:01,520 INFO    MainThread:36585 [wandb_init.py:setup_run_log_directory():687] Logging internal logs to sac_logging/wandb/run-20250903_104001-rj1c970k/logs/debug-internal.log
2025-09-03 10:40:01,520 INFO    MainThread:36585 [wandb_init.py:init():813] calling init triggers
2025-09-03 10:40:01,520 INFO    MainThread:36585 [wandb_init.py:init():818] wandb.init called with sweep_config: {}
config: {'env': {'name': 'HalfCheetah-v4', 'task': '', 'library': 'gym', 'max_episode_steps': 1000, 'seed': 42}, 'collector': {'total_frames': 1000000, 'init_random_frames': 25000, 'frames_per_batch': 1000, 'init_env_steps': 1000, 'device': None, 'env_per_collector': 8, 'reset_at_each_iter': False}, 'replay_buffer': {'size': 1000000, 'prb': 0, 'scratch_dir': None}, 'optim': {'utd_ratio': 1.0, 'gamma': 0.99, 'loss_function': 'l2', 'lr': 0.0003, 'weight_decay': 0.0, 'batch_size': 256, 'target_update_polyak': 0.995, 'alpha_init': 1.0, 'adam_eps': 1e-08}, 'network': {'hidden_sizes': [256, 256], 'activation': 'relu', 'default_policy_scale': 1.0, 'scale_lb': 0.1, 'device': None}, 'logger': {'backend': 'wandb', 'project_name': 'TOPR-RL', 'group_name': None, 'exp_name': '${env.name}_SAC_TorchRL', 'mode': 'online', 'eval_iter': 25000, 'video': False}, 'compile': {'compile': False, 'compile_mode': None, 'cudagraphs': False}, '_wandb': {}}
2025-09-03 10:40:01,520 INFO    MainThread:36585 [wandb_init.py:init():854] starting backend
2025-09-03 10:40:01,743 INFO    MainThread:36585 [wandb_init.py:init():857] sending inform_init request
2025-09-03 10:40:01,764 INFO    MainThread:36585 [wandb_init.py:init():865] backend started and connected
2025-09-03 10:40:01,767 INFO    MainThread:36585 [wandb_init.py:init():936] updated telemetry
2025-09-03 10:40:01,783 INFO    MainThread:36585 [wandb_init.py:init():960] communicating run to backend with 90.0 second timeout
2025-09-03 10:40:02,539 INFO    MainThread:36585 [wandb_init.py:init():1011] starting run threads in backend
2025-09-03 10:40:02,597 INFO    MainThread:36585 [wandb_run.py:_console_start():2494] atexit reg
2025-09-03 10:40:02,597 INFO    MainThread:36585 [wandb_run.py:_redirect():2342] redirect: wrap_raw
2025-09-03 10:40:02,597 INFO    MainThread:36585 [wandb_run.py:_redirect():2411] Wrapping output streams.
2025-09-03 10:40:02,597 INFO    MainThread:36585 [wandb_run.py:_redirect():2434] Redirects installed.
2025-09-03 10:40:02,598 INFO    MainThread:36585 [wandb_init.py:init():1057] run started, returning control to user process
2025-09-03 10:42:43,837 INFO    wandb-AsyncioManager-main:36585 [service_client.py:_forward_responses():84] Reached EOF.
2025-09-03 10:42:43,838 INFO    wandb-AsyncioManager-main:36585 [mailbox.py:close():137] Closing mailbox, abandoning 1 handles.
2025-09-03 10:42:44,290 ERROR   wandb-AsyncioManager-main:36585 [asyncio_manager.py:fn_wrap_exceptions():183] Uncaught exception in run_soon callback.
Traceback (most recent call last):
  File "/home/sebastian/anaconda3/envs/torch_rl/lib/python3.9/site-packages/wandb/sdk/lib/asyncio_manager.py", line 181, in fn_wrap_exceptions
    await fn()
  File "/home/sebastian/anaconda3/envs/torch_rl/lib/python3.9/site-packages/wandb/sdk/lib/service/service_client.py", line 65, in _send_server_request
    await self._writer.drain()
  File "/home/sebastian/anaconda3/envs/torch_rl/lib/python3.9/asyncio/streams.py", line 387, in drain
    await self._protocol._drain_helper()
  File "/home/sebastian/anaconda3/envs/torch_rl/lib/python3.9/asyncio/streams.py", line 190, in _drain_helper
    raise ConnectionResetError('Connection lost')
ConnectionResetError: Connection lost
2025-09-03 10:42:44,303 ERROR   wandb-AsyncioManager-main:36585 [asyncio_manager.py:fn_wrap_exceptions():183] Uncaught exception in run_soon callback.
Traceback (most recent call last):
  File "/home/sebastian/anaconda3/envs/torch_rl/lib/python3.9/site-packages/wandb/sdk/lib/asyncio_manager.py", line 181, in fn_wrap_exceptions
    await fn()
  File "/home/sebastian/anaconda3/envs/torch_rl/lib/python3.9/site-packages/wandb/sdk/lib/service/service_client.py", line 65, in _send_server_request
    await self._writer.drain()
  File "/home/sebastian/anaconda3/envs/torch_rl/lib/python3.9/asyncio/streams.py", line 387, in drain
    await self._protocol._drain_helper()
  File "/home/sebastian/anaconda3/envs/torch_rl/lib/python3.9/asyncio/streams.py", line 190, in _drain_helper
    raise ConnectionResetError('Connection lost')
ConnectionResetError: Connection lost
2025-09-03 10:42:44,303 ERROR   wandb-AsyncioManager-main:36585 [asyncio_manager.py:fn_wrap_exceptions():183] Uncaught exception in run_soon callback.
Traceback (most recent call last):
  File "/home/sebastian/anaconda3/envs/torch_rl/lib/python3.9/site-packages/wandb/sdk/lib/asyncio_manager.py", line 181, in fn_wrap_exceptions
    await fn()
  File "/home/sebastian/anaconda3/envs/torch_rl/lib/python3.9/site-packages/wandb/sdk/lib/service/service_client.py", line 65, in _send_server_request
    await self._writer.drain()
  File "/home/sebastian/anaconda3/envs/torch_rl/lib/python3.9/asyncio/streams.py", line 387, in drain
    await self._protocol._drain_helper()
  File "/home/sebastian/anaconda3/envs/torch_rl/lib/python3.9/asyncio/streams.py", line 190, in _drain_helper
    raise ConnectionResetError('Connection lost')
ConnectionResetError: Connection lost
2025-09-03 10:42:44,311 ERROR   wandb-AsyncioManager-main:36585 [asyncio_manager.py:fn_wrap_exceptions():183] Uncaught exception in run_soon callback.
Traceback (most recent call last):
  File "/home/sebastian/anaconda3/envs/torch_rl/lib/python3.9/site-packages/wandb/sdk/lib/asyncio_manager.py", line 181, in fn_wrap_exceptions
    await fn()
  File "/home/sebastian/anaconda3/envs/torch_rl/lib/python3.9/site-packages/wandb/sdk/lib/service/service_client.py", line 65, in _send_server_request
    await self._writer.drain()
  File "/home/sebastian/anaconda3/envs/torch_rl/lib/python3.9/asyncio/streams.py", line 387, in drain
    await self._protocol._drain_helper()
  File "/home/sebastian/anaconda3/envs/torch_rl/lib/python3.9/asyncio/streams.py", line 190, in _drain_helper
    raise ConnectionResetError('Connection lost')
ConnectionResetError: Connection lost
2025-09-03 10:42:44,312 ERROR   wandb-AsyncioManager-main:36585 [asyncio_manager.py:fn_wrap_exceptions():183] Uncaught exception in run_soon callback.
Traceback (most recent call last):
  File "/home/sebastian/anaconda3/envs/torch_rl/lib/python3.9/site-packages/wandb/sdk/lib/asyncio_manager.py", line 181, in fn_wrap_exceptions
    await fn()
  File "/home/sebastian/anaconda3/envs/torch_rl/lib/python3.9/site-packages/wandb/sdk/lib/service/service_client.py", line 65, in _send_server_request
    await self._writer.drain()
  File "/home/sebastian/anaconda3/envs/torch_rl/lib/python3.9/asyncio/streams.py", line 387, in drain
    await self._protocol._drain_helper()
  File "/home/sebastian/anaconda3/envs/torch_rl/lib/python3.9/asyncio/streams.py", line 190, in _drain_helper
    raise ConnectionResetError('Connection lost')
ConnectionResetError: Connection lost
2025-09-03 10:42:44,312 ERROR   wandb-AsyncioManager-main:36585 [asyncio_manager.py:fn_wrap_exceptions():183] Uncaught exception in run_soon callback.
Traceback (most recent call last):
  File "/home/sebastian/anaconda3/envs/torch_rl/lib/python3.9/site-packages/wandb/sdk/lib/asyncio_manager.py", line 181, in fn_wrap_exceptions
    await fn()
  File "/home/sebastian/anaconda3/envs/torch_rl/lib/python3.9/site-packages/wandb/sdk/lib/service/service_client.py", line 65, in _send_server_request
    await self._writer.drain()
  File "/home/sebastian/anaconda3/envs/torch_rl/lib/python3.9/asyncio/streams.py", line 387, in drain
    await self._protocol._drain_helper()
  File "/home/sebastian/anaconda3/envs/torch_rl/lib/python3.9/asyncio/streams.py", line 190, in _drain_helper
    raise ConnectionResetError('Connection lost')
ConnectionResetError: Connection lost
2025-09-03 10:42:44,313 ERROR   wandb-AsyncioManager-main:36585 [asyncio_manager.py:fn_wrap_exceptions():183] Uncaught exception in run_soon callback.
Traceback (most recent call last):
  File "/home/sebastian/anaconda3/envs/torch_rl/lib/python3.9/site-packages/wandb/sdk/lib/asyncio_manager.py", line 181, in fn_wrap_exceptions
    await fn()
  File "/home/sebastian/anaconda3/envs/torch_rl/lib/python3.9/site-packages/wandb/sdk/lib/service/service_client.py", line 65, in _send_server_request
    await self._writer.drain()
  File "/home/sebastian/anaconda3/envs/torch_rl/lib/python3.9/asyncio/streams.py", line 387, in drain
    await self._protocol._drain_helper()
  File "/home/sebastian/anaconda3/envs/torch_rl/lib/python3.9/asyncio/streams.py", line 190, in _drain_helper
    raise ConnectionResetError('Connection lost')
ConnectionResetError: Connection lost
2025-09-03 10:42:44,313 ERROR   wandb-AsyncioManager-main:36585 [asyncio_manager.py:fn_wrap_exceptions():183] Uncaught exception in run_soon callback.
Traceback (most recent call last):
  File "/home/sebastian/anaconda3/envs/torch_rl/lib/python3.9/site-packages/wandb/sdk/lib/asyncio_manager.py", line 181, in fn_wrap_exceptions
    await fn()
  File "/home/sebastian/anaconda3/envs/torch_rl/lib/python3.9/site-packages/wandb/sdk/lib/service/service_client.py", line 65, in _send_server_request
    await self._writer.drain()
  File "/home/sebastian/anaconda3/envs/torch_rl/lib/python3.9/asyncio/streams.py", line 387, in drain
    await self._protocol._drain_helper()
  File "/home/sebastian/anaconda3/envs/torch_rl/lib/python3.9/asyncio/streams.py", line 190, in _drain_helper
    raise ConnectionResetError('Connection lost')
ConnectionResetError: Connection lost
2025-09-03 10:42:44,313 ERROR   wandb-AsyncioManager-main:36585 [asyncio_manager.py:fn_wrap_exceptions():183] Uncaught exception in run_soon callback.
Traceback (most recent call last):
  File "/home/sebastian/anaconda3/envs/torch_rl/lib/python3.9/site-packages/wandb/sdk/lib/asyncio_manager.py", line 181, in fn_wrap_exceptions
    await fn()
  File "/home/sebastian/anaconda3/envs/torch_rl/lib/python3.9/site-packages/wandb/sdk/lib/service/service_client.py", line 65, in _send_server_request
    await self._writer.drain()
  File "/home/sebastian/anaconda3/envs/torch_rl/lib/python3.9/asyncio/streams.py", line 387, in drain
    await self._protocol._drain_helper()
  File "/home/sebastian/anaconda3/envs/torch_rl/lib/python3.9/asyncio/streams.py", line 190, in _drain_helper
    raise ConnectionResetError('Connection lost')
ConnectionResetError: Connection lost
2025-09-03 10:42:44,329 ERROR   wandb-AsyncioManager-main:36585 [asyncio_manager.py:fn_wrap_exceptions():183] Uncaught exception in run_soon callback.
Traceback (most recent call last):
  File "/home/sebastian/anaconda3/envs/torch_rl/lib/python3.9/site-packages/wandb/sdk/lib/asyncio_manager.py", line 181, in fn_wrap_exceptions
    await fn()
  File "/home/sebastian/anaconda3/envs/torch_rl/lib/python3.9/site-packages/wandb/sdk/lib/service/service_client.py", line 65, in _send_server_request
    await self._writer.drain()
  File "/home/sebastian/anaconda3/envs/torch_rl/lib/python3.9/asyncio/streams.py", line 387, in drain
    await self._protocol._drain_helper()
  File "/home/sebastian/anaconda3/envs/torch_rl/lib/python3.9/asyncio/streams.py", line 190, in _drain_helper
    raise ConnectionResetError('Connection lost')
ConnectionResetError: Connection lost
2025-09-03 10:42:44,329 ERROR   wandb-AsyncioManager-main:36585 [asyncio_manager.py:fn_wrap_exceptions():183] Uncaught exception in run_soon callback.
Traceback (most recent call last):
  File "/home/sebastian/anaconda3/envs/torch_rl/lib/python3.9/site-packages/wandb/sdk/lib/asyncio_manager.py", line 181, in fn_wrap_exceptions
    await fn()
  File "/home/sebastian/anaconda3/envs/torch_rl/lib/python3.9/site-packages/wandb/sdk/lib/service/service_client.py", line 65, in _send_server_request
    await self._writer.drain()
  File "/home/sebastian/anaconda3/envs/torch_rl/lib/python3.9/asyncio/streams.py", line 387, in drain
    await self._protocol._drain_helper()
  File "/home/sebastian/anaconda3/envs/torch_rl/lib/python3.9/asyncio/streams.py", line 190, in _drain_helper
    raise ConnectionResetError('Connection lost')
ConnectionResetError: Connection lost
2025-09-03 10:42:44,330 ERROR   wandb-AsyncioManager-main:36585 [asyncio_manager.py:fn_wrap_exceptions():183] Uncaught exception in run_soon callback.
Traceback (most recent call last):
  File "/home/sebastian/anaconda3/envs/torch_rl/lib/python3.9/site-packages/wandb/sdk/lib/asyncio_manager.py", line 181, in fn_wrap_exceptions
    await fn()
  File "/home/sebastian/anaconda3/envs/torch_rl/lib/python3.9/site-packages/wandb/sdk/lib/service/service_client.py", line 65, in _send_server_request
    await self._writer.drain()
  File "/home/sebastian/anaconda3/envs/torch_rl/lib/python3.9/asyncio/streams.py", line 387, in drain
    await self._protocol._drain_helper()
  File "/home/sebastian/anaconda3/envs/torch_rl/lib/python3.9/asyncio/streams.py", line 190, in _drain_helper
    raise ConnectionResetError('Connection lost')
ConnectionResetError: Connection lost
2025-09-03 10:42:44,330 ERROR   wandb-AsyncioManager-main:36585 [asyncio_manager.py:fn_wrap_exceptions():183] Uncaught exception in run_soon callback.
Traceback (most recent call last):
  File "/home/sebastian/anaconda3/envs/torch_rl/lib/python3.9/site-packages/wandb/sdk/lib/asyncio_manager.py", line 181, in fn_wrap_exceptions
    await fn()
  File "/home/sebastian/anaconda3/envs/torch_rl/lib/python3.9/site-packages/wandb/sdk/lib/service/service_client.py", line 65, in _send_server_request
    await self._writer.drain()
  File "/home/sebastian/anaconda3/envs/torch_rl/lib/python3.9/asyncio/streams.py", line 387, in drain
    await self._protocol._drain_helper()
  File "/home/sebastian/anaconda3/envs/torch_rl/lib/python3.9/asyncio/streams.py", line 190, in _drain_helper
    raise ConnectionResetError('Connection lost')
ConnectionResetError: Connection lost
2025-09-03 10:42:44,330 ERROR   wandb-AsyncioManager-main:36585 [asyncio_manager.py:fn_wrap_exceptions():183] Uncaught exception in run_soon callback.
Traceback (most recent call last):
  File "/home/sebastian/anaconda3/envs/torch_rl/lib/python3.9/site-packages/wandb/sdk/lib/asyncio_manager.py", line 181, in fn_wrap_exceptions
    await fn()
  File "/home/sebastian/anaconda3/envs/torch_rl/lib/python3.9/site-packages/wandb/sdk/lib/service/service_client.py", line 65, in _send_server_request
    await self._writer.drain()
  File "/home/sebastian/anaconda3/envs/torch_rl/lib/python3.9/asyncio/streams.py", line 387, in drain
    await self._protocol._drain_helper()
  File "/home/sebastian/anaconda3/envs/torch_rl/lib/python3.9/asyncio/streams.py", line 190, in _drain_helper
    raise ConnectionResetError('Connection lost')
ConnectionResetError: Connection lost
2025-09-03 10:42:44,330 ERROR   wandb-AsyncioManager-main:36585 [asyncio_manager.py:fn_wrap_exceptions():183] Uncaught exception in run_soon callback.
Traceback (most recent call last):
  File "/home/sebastian/anaconda3/envs/torch_rl/lib/python3.9/site-packages/wandb/sdk/lib/asyncio_manager.py", line 181, in fn_wrap_exceptions
    await fn()
  File "/home/sebastian/anaconda3/envs/torch_rl/lib/python3.9/site-packages/wandb/sdk/lib/service/service_client.py", line 65, in _send_server_request
    await self._writer.drain()
  File "/home/sebastian/anaconda3/envs/torch_rl/lib/python3.9/asyncio/streams.py", line 387, in drain
    await self._protocol._drain_helper()
  File "/home/sebastian/anaconda3/envs/torch_rl/lib/python3.9/asyncio/streams.py", line 190, in _drain_helper
    raise ConnectionResetError('Connection lost')
ConnectionResetError: Connection lost
2025-09-03 10:42:44,331 ERROR   wandb-AsyncioManager-main:36585 [asyncio_manager.py:fn_wrap_exceptions():183] Uncaught exception in run_soon callback.
Traceback (most recent call last):
  File "/home/sebastian/anaconda3/envs/torch_rl/lib/python3.9/site-packages/wandb/sdk/lib/asyncio_manager.py", line 181, in fn_wrap_exceptions
    await fn()
  File "/home/sebastian/anaconda3/envs/torch_rl/lib/python3.9/site-packages/wandb/sdk/lib/service/service_client.py", line 65, in _send_server_request
    await self._writer.drain()
  File "/home/sebastian/anaconda3/envs/torch_rl/lib/python3.9/asyncio/streams.py", line 387, in drain
    await self._protocol._drain_helper()
  File "/home/sebastian/anaconda3/envs/torch_rl/lib/python3.9/asyncio/streams.py", line 190, in _drain_helper
    raise ConnectionResetError('Connection lost')
ConnectionResetError: Connection lost
2025-09-03 10:42:44,331 ERROR   wandb-AsyncioManager-main:36585 [asyncio_manager.py:fn_wrap_exceptions():183] Uncaught exception in run_soon callback.
Traceback (most recent call last):
  File "/home/sebastian/anaconda3/envs/torch_rl/lib/python3.9/site-packages/wandb/sdk/lib/asyncio_manager.py", line 181, in fn_wrap_exceptions
    await fn()
  File "/home/sebastian/anaconda3/envs/torch_rl/lib/python3.9/site-packages/wandb/sdk/lib/service/service_client.py", line 65, in _send_server_request
    await self._writer.drain()
  File "/home/sebastian/anaconda3/envs/torch_rl/lib/python3.9/asyncio/streams.py", line 387, in drain
    await self._protocol._drain_helper()
  File "/home/sebastian/anaconda3/envs/torch_rl/lib/python3.9/asyncio/streams.py", line 190, in _drain_helper
    raise ConnectionResetError('Connection lost')
ConnectionResetError: Connection lost
2025-09-03 10:42:44,331 ERROR   wandb-AsyncioManager-main:36585 [asyncio_manager.py:fn_wrap_exceptions():183] Uncaught exception in run_soon callback.
Traceback (most recent call last):
  File "/home/sebastian/anaconda3/envs/torch_rl/lib/python3.9/site-packages/wandb/sdk/lib/asyncio_manager.py", line 181, in fn_wrap_exceptions
    await fn()
  File "/home/sebastian/anaconda3/envs/torch_rl/lib/python3.9/site-packages/wandb/sdk/lib/service/service_client.py", line 65, in _send_server_request
    await self._writer.drain()
  File "/home/sebastian/anaconda3/envs/torch_rl/lib/python3.9/asyncio/streams.py", line 387, in drain
    await self._protocol._drain_helper()
  File "/home/sebastian/anaconda3/envs/torch_rl/lib/python3.9/asyncio/streams.py", line 190, in _drain_helper
    raise ConnectionResetError('Connection lost')
ConnectionResetError: Connection lost
2025-09-03 10:42:44,331 ERROR   wandb-AsyncioManager-main:36585 [asyncio_manager.py:fn_wrap_exceptions():183] Uncaught exception in run_soon callback.
Traceback (most recent call last):
  File "/home/sebastian/anaconda3/envs/torch_rl/lib/python3.9/site-packages/wandb/sdk/lib/asyncio_manager.py", line 181, in fn_wrap_exceptions
    await fn()
  File "/home/sebastian/anaconda3/envs/torch_rl/lib/python3.9/site-packages/wandb/sdk/lib/service/service_client.py", line 65, in _send_server_request
    await self._writer.drain()
  File "/home/sebastian/anaconda3/envs/torch_rl/lib/python3.9/asyncio/streams.py", line 387, in drain
    await self._protocol._drain_helper()
  File "/home/sebastian/anaconda3/envs/torch_rl/lib/python3.9/asyncio/streams.py", line 190, in _drain_helper
    raise ConnectionResetError('Connection lost')
ConnectionResetError: Connection lost
2025-09-03 10:42:44,332 ERROR   wandb-AsyncioManager-main:36585 [asyncio_manager.py:fn_wrap_exceptions():183] Uncaught exception in run_soon callback.
Traceback (most recent call last):
  File "/home/sebastian/anaconda3/envs/torch_rl/lib/python3.9/site-packages/wandb/sdk/lib/asyncio_manager.py", line 181, in fn_wrap_exceptions
    await fn()
  File "/home/sebastian/anaconda3/envs/torch_rl/lib/python3.9/site-packages/wandb/sdk/lib/service/service_client.py", line 65, in _send_server_request
    await self._writer.drain()
  File "/home/sebastian/anaconda3/envs/torch_rl/lib/python3.9/asyncio/streams.py", line 387, in drain
    await self._protocol._drain_helper()
  File "/home/sebastian/anaconda3/envs/torch_rl/lib/python3.9/asyncio/streams.py", line 190, in _drain_helper
    raise ConnectionResetError('Connection lost')
ConnectionResetError: Connection lost
2025-09-03 10:42:44,333 ERROR   wandb-AsyncioManager-main:36585 [asyncio_manager.py:fn_wrap_exceptions():183] Uncaught exception in run_soon callback.
Traceback (most recent call last):
  File "/home/sebastian/anaconda3/envs/torch_rl/lib/python3.9/site-packages/wandb/sdk/lib/asyncio_manager.py", line 181, in fn_wrap_exceptions
    await fn()
  File "/home/sebastian/anaconda3/envs/torch_rl/lib/python3.9/site-packages/wandb/sdk/lib/service/service_client.py", line 65, in _send_server_request
    await self._writer.drain()
  File "/home/sebastian/anaconda3/envs/torch_rl/lib/python3.9/asyncio/streams.py", line 387, in drain
    await self._protocol._drain_helper()
  File "/home/sebastian/anaconda3/envs/torch_rl/lib/python3.9/asyncio/streams.py", line 190, in _drain_helper
    raise ConnectionResetError('Connection lost')
ConnectionResetError: Connection lost
2025-09-03 10:42:44,333 ERROR   wandb-AsyncioManager-main:36585 [asyncio_manager.py:fn_wrap_exceptions():183] Uncaught exception in run_soon callback.
Traceback (most recent call last):
  File "/home/sebastian/anaconda3/envs/torch_rl/lib/python3.9/site-packages/wandb/sdk/lib/asyncio_manager.py", line 181, in fn_wrap_exceptions
    await fn()
  File "/home/sebastian/anaconda3/envs/torch_rl/lib/python3.9/site-packages/wandb/sdk/lib/service/service_client.py", line 65, in _send_server_request
    await self._writer.drain()
  File "/home/sebastian/anaconda3/envs/torch_rl/lib/python3.9/asyncio/streams.py", line 387, in drain
    await self._protocol._drain_helper()
  File "/home/sebastian/anaconda3/envs/torch_rl/lib/python3.9/asyncio/streams.py", line 190, in _drain_helper
    raise ConnectionResetError('Connection lost')
ConnectionResetError: Connection lost
2025-09-03 10:42:44,333 ERROR   wandb-AsyncioManager-main:36585 [asyncio_manager.py:fn_wrap_exceptions():183] Uncaught exception in run_soon callback.
Traceback (most recent call last):
  File "/home/sebastian/anaconda3/envs/torch_rl/lib/python3.9/site-packages/wandb/sdk/lib/asyncio_manager.py", line 181, in fn_wrap_exceptions
    await fn()
  File "/home/sebastian/anaconda3/envs/torch_rl/lib/python3.9/site-packages/wandb/sdk/lib/service/service_client.py", line 65, in _send_server_request
    await self._writer.drain()
  File "/home/sebastian/anaconda3/envs/torch_rl/lib/python3.9/asyncio/streams.py", line 387, in drain
    await self._protocol._drain_helper()
  File "/home/sebastian/anaconda3/envs/torch_rl/lib/python3.9/asyncio/streams.py", line 190, in _drain_helper
    raise ConnectionResetError('Connection lost')
ConnectionResetError: Connection lost
2025-09-03 10:42:44,333 ERROR   wandb-AsyncioManager-main:36585 [asyncio_manager.py:fn_wrap_exceptions():183] Uncaught exception in run_soon callback.
Traceback (most recent call last):
  File "/home/sebastian/anaconda3/envs/torch_rl/lib/python3.9/site-packages/wandb/sdk/lib/asyncio_manager.py", line 181, in fn_wrap_exceptions
    await fn()
  File "/home/sebastian/anaconda3/envs/torch_rl/lib/python3.9/site-packages/wandb/sdk/lib/service/service_client.py", line 65, in _send_server_request
    await self._writer.drain()
  File "/home/sebastian/anaconda3/envs/torch_rl/lib/python3.9/asyncio/streams.py", line 387, in drain
    await self._protocol._drain_helper()
  File "/home/sebastian/anaconda3/envs/torch_rl/lib/python3.9/asyncio/streams.py", line 190, in _drain_helper
    raise ConnectionResetError('Connection lost')
ConnectionResetError: Connection lost
2025-09-03 10:42:44,333 ERROR   wandb-AsyncioManager-main:36585 [asyncio_manager.py:fn_wrap_exceptions():183] Uncaught exception in run_soon callback.
Traceback (most recent call last):
  File "/home/sebastian/anaconda3/envs/torch_rl/lib/python3.9/site-packages/wandb/sdk/lib/asyncio_manager.py", line 181, in fn_wrap_exceptions
    await fn()
  File "/home/sebastian/anaconda3/envs/torch_rl/lib/python3.9/site-packages/wandb/sdk/lib/service/service_client.py", line 65, in _send_server_request
    await self._writer.drain()
  File "/home/sebastian/anaconda3/envs/torch_rl/lib/python3.9/asyncio/streams.py", line 387, in drain
    await self._protocol._drain_helper()
  File "/home/sebastian/anaconda3/envs/torch_rl/lib/python3.9/asyncio/streams.py", line 190, in _drain_helper
    raise ConnectionResetError('Connection lost')
ConnectionResetError: Connection lost
2025-09-03 10:42:44,333 ERROR   wandb-AsyncioManager-main:36585 [asyncio_manager.py:fn_wrap_exceptions():183] Uncaught exception in run_soon callback.
Traceback (most recent call last):
  File "/home/sebastian/anaconda3/envs/torch_rl/lib/python3.9/site-packages/wandb/sdk/lib/asyncio_manager.py", line 181, in fn_wrap_exceptions
    await fn()
  File "/home/sebastian/anaconda3/envs/torch_rl/lib/python3.9/site-packages/wandb/sdk/lib/service/service_client.py", line 65, in _send_server_request
    await self._writer.drain()
  File "/home/sebastian/anaconda3/envs/torch_rl/lib/python3.9/asyncio/streams.py", line 387, in drain
    await self._protocol._drain_helper()
  File "/home/sebastian/anaconda3/envs/torch_rl/lib/python3.9/asyncio/streams.py", line 190, in _drain_helper
    raise ConnectionResetError('Connection lost')
ConnectionResetError: Connection lost
2025-09-03 10:42:44,333 ERROR   wandb-AsyncioManager-main:36585 [asyncio_manager.py:fn_wrap_exceptions():183] Uncaught exception in run_soon callback.
Traceback (most recent call last):
  File "/home/sebastian/anaconda3/envs/torch_rl/lib/python3.9/site-packages/wandb/sdk/lib/asyncio_manager.py", line 181, in fn_wrap_exceptions
    await fn()
  File "/home/sebastian/anaconda3/envs/torch_rl/lib/python3.9/site-packages/wandb/sdk/lib/service/service_client.py", line 65, in _send_server_request
    await self._writer.drain()
  File "/home/sebastian/anaconda3/envs/torch_rl/lib/python3.9/asyncio/streams.py", line 387, in drain
    await self._protocol._drain_helper()
  File "/home/sebastian/anaconda3/envs/torch_rl/lib/python3.9/asyncio/streams.py", line 190, in _drain_helper
    raise ConnectionResetError('Connection lost')
ConnectionResetError: Connection lost
2025-09-03 10:42:44,333 ERROR   wandb-AsyncioManager-main:36585 [asyncio_manager.py:fn_wrap_exceptions():183] Uncaught exception in run_soon callback.
Traceback (most recent call last):
  File "/home/sebastian/anaconda3/envs/torch_rl/lib/python3.9/site-packages/wandb/sdk/lib/asyncio_manager.py", line 181, in fn_wrap_exceptions
    await fn()
  File "/home/sebastian/anaconda3/envs/torch_rl/lib/python3.9/site-packages/wandb/sdk/lib/service/service_client.py", line 65, in _send_server_request
    await self._writer.drain()
  File "/home/sebastian/anaconda3/envs/torch_rl/lib/python3.9/asyncio/streams.py", line 387, in drain
    await self._protocol._drain_helper()
  File "/home/sebastian/anaconda3/envs/torch_rl/lib/python3.9/asyncio/streams.py", line 190, in _drain_helper
    raise ConnectionResetError('Connection lost')
ConnectionResetError: Connection lost
2025-09-03 10:42:44,334 ERROR   wandb-AsyncioManager-main:36585 [asyncio_manager.py:fn_wrap_exceptions():183] Uncaught exception in run_soon callback.
Traceback (most recent call last):
  File "/home/sebastian/anaconda3/envs/torch_rl/lib/python3.9/site-packages/wandb/sdk/lib/asyncio_manager.py", line 181, in fn_wrap_exceptions
    await fn()
  File "/home/sebastian/anaconda3/envs/torch_rl/lib/python3.9/site-packages/wandb/sdk/lib/service/service_client.py", line 65, in _send_server_request
    await self._writer.drain()
  File "/home/sebastian/anaconda3/envs/torch_rl/lib/python3.9/asyncio/streams.py", line 387, in drain
    await self._protocol._drain_helper()
  File "/home/sebastian/anaconda3/envs/torch_rl/lib/python3.9/asyncio/streams.py", line 190, in _drain_helper
    raise ConnectionResetError('Connection lost')
ConnectionResetError: Connection lost
2025-09-03 10:42:44,334 ERROR   wandb-AsyncioManager-main:36585 [asyncio_manager.py:fn_wrap_exceptions():183] Uncaught exception in run_soon callback.
Traceback (most recent call last):
  File "/home/sebastian/anaconda3/envs/torch_rl/lib/python3.9/site-packages/wandb/sdk/lib/asyncio_manager.py", line 181, in fn_wrap_exceptions
    await fn()
  File "/home/sebastian/anaconda3/envs/torch_rl/lib/python3.9/site-packages/wandb/sdk/lib/service/service_client.py", line 65, in _send_server_request
    await self._writer.drain()
  File "/home/sebastian/anaconda3/envs/torch_rl/lib/python3.9/asyncio/streams.py", line 387, in drain
    await self._protocol._drain_helper()
  File "/home/sebastian/anaconda3/envs/torch_rl/lib/python3.9/asyncio/streams.py", line 190, in _drain_helper
    raise ConnectionResetError('Connection lost')
ConnectionResetError: Connection lost
2025-09-03 10:42:44,334 ERROR   wandb-AsyncioManager-main:36585 [asyncio_manager.py:fn_wrap_exceptions():183] Uncaught exception in run_soon callback.
Traceback (most recent call last):
  File "/home/sebastian/anaconda3/envs/torch_rl/lib/python3.9/site-packages/wandb/sdk/lib/asyncio_manager.py", line 181, in fn_wrap_exceptions
    await fn()
  File "/home/sebastian/anaconda3/envs/torch_rl/lib/python3.9/site-packages/wandb/sdk/lib/service/service_client.py", line 65, in _send_server_request
    await self._writer.drain()
  File "/home/sebastian/anaconda3/envs/torch_rl/lib/python3.9/asyncio/streams.py", line 387, in drain
    await self._protocol._drain_helper()
  File "/home/sebastian/anaconda3/envs/torch_rl/lib/python3.9/asyncio/streams.py", line 190, in _drain_helper
    raise ConnectionResetError('Connection lost')
ConnectionResetError: Connection lost
2025-09-03 10:42:44,334 ERROR   wandb-AsyncioManager-main:36585 [asyncio_manager.py:fn_wrap_exceptions():183] Uncaught exception in run_soon callback.
Traceback (most recent call last):
  File "/home/sebastian/anaconda3/envs/torch_rl/lib/python3.9/site-packages/wandb/sdk/lib/asyncio_manager.py", line 181, in fn_wrap_exceptions
    await fn()
  File "/home/sebastian/anaconda3/envs/torch_rl/lib/python3.9/site-packages/wandb/sdk/lib/service/service_client.py", line 65, in _send_server_request
    await self._writer.drain()
  File "/home/sebastian/anaconda3/envs/torch_rl/lib/python3.9/asyncio/streams.py", line 387, in drain
    await self._protocol._drain_helper()
  File "/home/sebastian/anaconda3/envs/torch_rl/lib/python3.9/asyncio/streams.py", line 190, in _drain_helper
    raise ConnectionResetError('Connection lost')
ConnectionResetError: Connection lost
2025-09-03 10:42:44,334 ERROR   wandb-AsyncioManager-main:36585 [asyncio_manager.py:fn_wrap_exceptions():183] Uncaught exception in run_soon callback.
Traceback (most recent call last):
  File "/home/sebastian/anaconda3/envs/torch_rl/lib/python3.9/site-packages/wandb/sdk/lib/asyncio_manager.py", line 181, in fn_wrap_exceptions
    await fn()
  File "/home/sebastian/anaconda3/envs/torch_rl/lib/python3.9/site-packages/wandb/sdk/lib/service/service_client.py", line 65, in _send_server_request
    await self._writer.drain()
  File "/home/sebastian/anaconda3/envs/torch_rl/lib/python3.9/asyncio/streams.py", line 387, in drain
    await self._protocol._drain_helper()
  File "/home/sebastian/anaconda3/envs/torch_rl/lib/python3.9/asyncio/streams.py", line 190, in _drain_helper
    raise ConnectionResetError('Connection lost')
ConnectionResetError: Connection lost
2025-09-03 10:42:44,335 ERROR   wandb-AsyncioManager-main:36585 [asyncio_manager.py:fn_wrap_exceptions():183] Uncaught exception in run_soon callback.
Traceback (most recent call last):
  File "/home/sebastian/anaconda3/envs/torch_rl/lib/python3.9/site-packages/wandb/sdk/lib/asyncio_manager.py", line 181, in fn_wrap_exceptions
    await fn()
  File "/home/sebastian/anaconda3/envs/torch_rl/lib/python3.9/site-packages/wandb/sdk/lib/service/service_client.py", line 65, in _send_server_request
    await self._writer.drain()
  File "/home/sebastian/anaconda3/envs/torch_rl/lib/python3.9/asyncio/streams.py", line 387, in drain
    await self._protocol._drain_helper()
  File "/home/sebastian/anaconda3/envs/torch_rl/lib/python3.9/asyncio/streams.py", line 190, in _drain_helper
    raise ConnectionResetError('Connection lost')
ConnectionResetError: Connection lost
2025-09-03 10:42:44,335 ERROR   wandb-AsyncioManager-main:36585 [asyncio_manager.py:fn_wrap_exceptions():183] Uncaught exception in run_soon callback.
Traceback (most recent call last):
  File "/home/sebastian/anaconda3/envs/torch_rl/lib/python3.9/site-packages/wandb/sdk/lib/asyncio_manager.py", line 181, in fn_wrap_exceptions
    await fn()
  File "/home/sebastian/anaconda3/envs/torch_rl/lib/python3.9/site-packages/wandb/sdk/lib/service/service_client.py", line 65, in _send_server_request
    await self._writer.drain()
  File "/home/sebastian/anaconda3/envs/torch_rl/lib/python3.9/asyncio/streams.py", line 387, in drain
    await self._protocol._drain_helper()
  File "/home/sebastian/anaconda3/envs/torch_rl/lib/python3.9/asyncio/streams.py", line 190, in _drain_helper
    raise ConnectionResetError('Connection lost')
ConnectionResetError: Connection lost
2025-09-03 10:42:44,335 ERROR   wandb-AsyncioManager-main:36585 [asyncio_manager.py:fn_wrap_exceptions():183] Uncaught exception in run_soon callback.
Traceback (most recent call last):
  File "/home/sebastian/anaconda3/envs/torch_rl/lib/python3.9/site-packages/wandb/sdk/lib/asyncio_manager.py", line 181, in fn_wrap_exceptions
    await fn()
  File "/home/sebastian/anaconda3/envs/torch_rl/lib/python3.9/site-packages/wandb/sdk/lib/service/service_client.py", line 65, in _send_server_request
    await self._writer.drain()
  File "/home/sebastian/anaconda3/envs/torch_rl/lib/python3.9/asyncio/streams.py", line 387, in drain
    await self._protocol._drain_helper()
  File "/home/sebastian/anaconda3/envs/torch_rl/lib/python3.9/asyncio/streams.py", line 190, in _drain_helper
    raise ConnectionResetError('Connection lost')
ConnectionResetError: Connection lost
2025-09-03 10:42:44,335 ERROR   wandb-AsyncioManager-main:36585 [asyncio_manager.py:fn_wrap_exceptions():183] Uncaught exception in run_soon callback.
Traceback (most recent call last):
  File "/home/sebastian/anaconda3/envs/torch_rl/lib/python3.9/site-packages/wandb/sdk/lib/asyncio_manager.py", line 181, in fn_wrap_exceptions
    await fn()
  File "/home/sebastian/anaconda3/envs/torch_rl/lib/python3.9/site-packages/wandb/sdk/lib/service/service_client.py", line 65, in _send_server_request
    await self._writer.drain()
  File "/home/sebastian/anaconda3/envs/torch_rl/lib/python3.9/asyncio/streams.py", line 387, in drain
    await self._protocol._drain_helper()
  File "/home/sebastian/anaconda3/envs/torch_rl/lib/python3.9/asyncio/streams.py", line 190, in _drain_helper
    raise ConnectionResetError('Connection lost')
ConnectionResetError: Connection lost
2025-09-03 10:42:44,335 ERROR   wandb-AsyncioManager-main:36585 [asyncio_manager.py:fn_wrap_exceptions():183] Uncaught exception in run_soon callback.
Traceback (most recent call last):
  File "/home/sebastian/anaconda3/envs/torch_rl/lib/python3.9/site-packages/wandb/sdk/lib/asyncio_manager.py", line 181, in fn_wrap_exceptions
    await fn()
  File "/home/sebastian/anaconda3/envs/torch_rl/lib/python3.9/site-packages/wandb/sdk/lib/service/service_client.py", line 65, in _send_server_request
    await self._writer.drain()
  File "/home/sebastian/anaconda3/envs/torch_rl/lib/python3.9/asyncio/streams.py", line 387, in drain
    await self._protocol._drain_helper()
  File "/home/sebastian/anaconda3/envs/torch_rl/lib/python3.9/asyncio/streams.py", line 190, in _drain_helper
    raise ConnectionResetError('Connection lost')
ConnectionResetError: Connection lost
2025-09-03 10:42:44,335 ERROR   wandb-AsyncioManager-main:36585 [asyncio_manager.py:fn_wrap_exceptions():183] Uncaught exception in run_soon callback.
Traceback (most recent call last):
  File "/home/sebastian/anaconda3/envs/torch_rl/lib/python3.9/site-packages/wandb/sdk/lib/asyncio_manager.py", line 181, in fn_wrap_exceptions
    await fn()
  File "/home/sebastian/anaconda3/envs/torch_rl/lib/python3.9/site-packages/wandb/sdk/lib/service/service_client.py", line 65, in _send_server_request
    await self._writer.drain()
  File "/home/sebastian/anaconda3/envs/torch_rl/lib/python3.9/asyncio/streams.py", line 387, in drain
    await self._protocol._drain_helper()
  File "/home/sebastian/anaconda3/envs/torch_rl/lib/python3.9/asyncio/streams.py", line 190, in _drain_helper
    raise ConnectionResetError('Connection lost')
ConnectionResetError: Connection lost
2025-09-03 10:42:44,335 ERROR   wandb-AsyncioManager-main:36585 [asyncio_manager.py:fn_wrap_exceptions():183] Uncaught exception in run_soon callback.
Traceback (most recent call last):
  File "/home/sebastian/anaconda3/envs/torch_rl/lib/python3.9/site-packages/wandb/sdk/lib/asyncio_manager.py", line 181, in fn_wrap_exceptions
    await fn()
  File "/home/sebastian/anaconda3/envs/torch_rl/lib/python3.9/site-packages/wandb/sdk/lib/service/service_client.py", line 65, in _send_server_request
    await self._writer.drain()
  File "/home/sebastian/anaconda3/envs/torch_rl/lib/python3.9/asyncio/streams.py", line 387, in drain
    await self._protocol._drain_helper()
  File "/home/sebastian/anaconda3/envs/torch_rl/lib/python3.9/asyncio/streams.py", line 190, in _drain_helper
    raise ConnectionResetError('Connection lost')
ConnectionResetError: Connection lost
2025-09-03 10:42:44,335 ERROR   wandb-AsyncioManager-main:36585 [asyncio_manager.py:fn_wrap_exceptions():183] Uncaught exception in run_soon callback.
Traceback (most recent call last):
  File "/home/sebastian/anaconda3/envs/torch_rl/lib/python3.9/site-packages/wandb/sdk/lib/asyncio_manager.py", line 181, in fn_wrap_exceptions
    await fn()
  File "/home/sebastian/anaconda3/envs/torch_rl/lib/python3.9/site-packages/wandb/sdk/lib/service/service_client.py", line 65, in _send_server_request
    await self._writer.drain()
  File "/home/sebastian/anaconda3/envs/torch_rl/lib/python3.9/asyncio/streams.py", line 387, in drain
    await self._protocol._drain_helper()
  File "/home/sebastian/anaconda3/envs/torch_rl/lib/python3.9/asyncio/streams.py", line 190, in _drain_helper
    raise ConnectionResetError('Connection lost')
ConnectionResetError: Connection lost
2025-09-03 10:42:44,335 ERROR   wandb-AsyncioManager-main:36585 [asyncio_manager.py:fn_wrap_exceptions():183] Uncaught exception in run_soon callback.
Traceback (most recent call last):
  File "/home/sebastian/anaconda3/envs/torch_rl/lib/python3.9/site-packages/wandb/sdk/lib/asyncio_manager.py", line 181, in fn_wrap_exceptions
    await fn()
  File "/home/sebastian/anaconda3/envs/torch_rl/lib/python3.9/site-packages/wandb/sdk/lib/service/service_client.py", line 65, in _send_server_request
    await self._writer.drain()
  File "/home/sebastian/anaconda3/envs/torch_rl/lib/python3.9/asyncio/streams.py", line 387, in drain
    await self._protocol._drain_helper()
  File "/home/sebastian/anaconda3/envs/torch_rl/lib/python3.9/asyncio/streams.py", line 190, in _drain_helper
    raise ConnectionResetError('Connection lost')
ConnectionResetError: Connection lost
2025-09-03 10:42:44,336 ERROR   wandb-AsyncioManager-main:36585 [asyncio_manager.py:fn_wrap_exceptions():183] Uncaught exception in run_soon callback.
Traceback (most recent call last):
  File "/home/sebastian/anaconda3/envs/torch_rl/lib/python3.9/site-packages/wandb/sdk/lib/asyncio_manager.py", line 181, in fn_wrap_exceptions
    await fn()
  File "/home/sebastian/anaconda3/envs/torch_rl/lib/python3.9/site-packages/wandb/sdk/lib/service/service_client.py", line 65, in _send_server_request
    await self._writer.drain()
  File "/home/sebastian/anaconda3/envs/torch_rl/lib/python3.9/asyncio/streams.py", line 387, in drain
    await self._protocol._drain_helper()
  File "/home/sebastian/anaconda3/envs/torch_rl/lib/python3.9/asyncio/streams.py", line 190, in _drain_helper
    raise ConnectionResetError('Connection lost')
ConnectionResetError: Connection lost
2025-09-03 10:42:44,336 ERROR   wandb-AsyncioManager-main:36585 [asyncio_manager.py:fn_wrap_exceptions():183] Uncaught exception in run_soon callback.
Traceback (most recent call last):
  File "/home/sebastian/anaconda3/envs/torch_rl/lib/python3.9/site-packages/wandb/sdk/lib/asyncio_manager.py", line 181, in fn_wrap_exceptions
    await fn()
  File "/home/sebastian/anaconda3/envs/torch_rl/lib/python3.9/site-packages/wandb/sdk/lib/service/service_client.py", line 65, in _send_server_request
    await self._writer.drain()
  File "/home/sebastian/anaconda3/envs/torch_rl/lib/python3.9/asyncio/streams.py", line 387, in drain
    await self._protocol._drain_helper()
  File "/home/sebastian/anaconda3/envs/torch_rl/lib/python3.9/asyncio/streams.py", line 190, in _drain_helper
    raise ConnectionResetError('Connection lost')
ConnectionResetError: Connection lost
